<?xml version="1.0" ?>
<robot name="rover_bot" xmlns:xarco="http://www.ros.org/wiki/xacro">
  <gazebo reference="link_chassis">
    <material>Gazebo/Red</material>
  </gazebo>
  <gazebo>
    <plugin name="skid_steer_drive_controller" filename="libgazebo_ros_skid_steer_drive.so">
      <updateRate>100.0</updateRate>
      <robotNamespace>/</robotNamespace>
      <leftFrontJoint>front_left_wheel_joint</leftFrontJoint>
      <rightFrontJoint>front_right_wheel_joint</rightFrontJoint>
      <leftRearJoint>back_left_wheel_joint</leftRearJoint>
      <rightRearJoint>back_right_wheel_joint</rightRearJoint>
      <wheelSeparation>0.15</wheelSeparation>
      <wheelDiameter>0.065</wheelDiameter>
      <robotBaseFrame>base_link</robotBaseFrame>
      <torque>0.0343</torque>
      <topicName>cmd_vel</topicName>
      <broadcastTF>false</broadcastTF>
    </plugin>
  </gazebo>
<link name="link_chassis">
  <pose>0 0 0.325 0 0 0</pose>
  <inertial>
    <mass value = "0.04"/>
    <inertia ixx="0.00395416666667" ixy="0" ixz="0" iyy="0.0106208333333" iyz="0" izz="0.0106208333333"/>
  </inertial>
  <collision>
    <geometry>
      <box size="0.196 0.15 0.025"/>
    </geometry>
  </collision>
  <visual>
    <geometry>
      <box size="0.196 0.15 0.025"/>
    </geometry>
  </visual>
</link>
<!-- defining wheels -->
<link name="link_front_right_wheel">
  <inertial>
    <mass value="0.034"/>
    <origin rpy="0 1.5707 1.5707" xyz="0 0 0"/>
    <inertia ixx="0.0000526666666667" ixy="0" ixz="0" iyy="0.0000526666666667" iyz="0" izz="0.0001"/>
  </inertial>
  <collision name="link_front_right_wheel_collision">
    <origin rpy="0 1.5707 1.5707" xyz="0 0 0"/>
    <geometry>
      <cylinder length="0.025" radius="0.0325"/>
    </geometry>
  </collision>
  <visual name="link_front_right_wheel_visual">
    <origin rpy="0 1.5707 1.5707" xyz="0 0 0"/>
    <geometry>
      <cylinder length="0.025" radius="0.0325"/>
    </geometry>
  </visual>
</link>
<link name="link_front_left_wheel">
  <inertial>
    <mass value="0.034"/>
    <origin rpy="0 1.5707 1.5707" xyz="0 0 0"/>
    <inertia ixx="0.000526666666667" ixy="0" ixz="0" iyy="0.000526666666667" iyz="0" izz="0.001"/>
  </inertial>
  <collision name="link_front_left_wheel_collision">
    <origin rpy="0 1.5707 1.5707" xyz="0 0 0"/>
    <geometry>
      <cylinder length="0.025" radius="0.0325"/>
    </geometry>
  </collision>
  <visual name="link_front_left_wheel_visual">
    <origin rpy="0 1.5707 1.5707" xyz="0 0 0"/>
    <geometry>
      <cylinder length="0.025" radius="0.0325"/>
    </geometry>
  </visual>
</link>
<link name="link_back_right_wheel">
  <inertial>
    <mass value="0.034"/>
    <origin rpy="0 1.5707 1.5707" xyz="0 0 0"/>
    <inertia ixx="0.000526666666667" ixy="0" ixz="0" iyy="0.000526666666667" iyz="0" izz="0.001"/>
  </inertial>
  <collision name="link_back_right_wheel_collision">
    <origin rpy="0 1.5707 1.5707" xyz="0 0 0"/>
    <geometry>
      <cylinder length="0.025" radius="0.0325"/>
    </geometry>
  </collision>
  <visual name="link_back_right_wheel_visual">
    <origin rpy="0 1.5707 1.5707" xyz="0 0 0"/>
    <geometry>
      <cylinder length="0.025" radius="0.0325"/>
    </geometry>
  </visual>
</link>
<link name="link_back_left_wheel">
  <inertial>
    <mass value="0.034"/>
    <origin rpy="0 1.5707 1.5707" xyz="0 0 0"/>
    <inertia ixx="0.000526666666667" ixy="0" ixz="0" iyy="0.000526666666667" iyz="0" izz="0.001"/>
  </inertial>
  <collision name="link_back_left_wheel_collision">
    <origin rpy="0 1.5707 1.5707" xyz="0 0 0"/>
    <geometry>
      <cylinder length="0.025" radius="0.0325"/>
    </geometry>
  </collision>
  <visual name="link_back_left_wheel_visual">
    <origin rpy="0 1.5707 1.5707" xyz="0 0 0"/>
    <geometry>
      <cylinder length="0.025" radius="0.0325"/>
    </geometry>
  </visual>
</link>
<!-- defining joints -->
<joint name="front_right_wheel_joint" type="continuous">
  <origin rpy="0 0 0" xyz="0.083 0.075 0"/>
  <child link="link_front_right_wheel"/>
  <parent link="link_chassis"/>
  <axis rpy="0 0 0" xyz="0 1 0"/>
  <limit effort="100" velocity="1"/>
  <joint_properties damping="1.0" friction="1.0"/>
</joint>
<joint name="front_left_wheel_joint" type="continuous">
  <origin rpy="0 0 0" xyz="0.083 -0.075 0"/>
  <child link="link_front_left_wheel"/>
  <parent link="link_chassis"/>
  <axis rpy="0 0 0" xyz="0 1 0"/>
  <limit effort="100" velocity="1"/>
  <joint_properties damping="1.0" friction="1.0"/>
</joint>
<joint name="back_right_wheel_joint" type="continuous">
  <origin rpy="0 0 0" xyz="-0.083 0.075 0"/>
  <child link="link_back_right_wheel"/>
  <parent link="link_chassis"/>
  <axis rpy="0 0 0" xyz="0 1 0"/>
  <limit effort="100" velocity="1"/>
  <joint_properties damping="1.0" friction="1.0"/>
</joint>
<joint name="back_left_wheel_joint" type="continuous">
  <origin rpy="0 0 0" xyz="-0.083 -0.075 0"/>
  <child link="link_back_left_wheel"/>
  <parent link="link_chassis"/>
  <axis rpy="0 0 0" xyz="0 1 0"/>
  <limit effort="100" velocity="1"/>
  <joint_properties damping="1.0" friction="1.0"/>
</joint>

 <!-- camera -->
  <gazebo reference="camera_link">
    <sensor type="camera" name="camera1">
      <update_rate>30.0</update_rate>
      <camera name="head">
        <horizontal_fov>1.3962634</horizontal_fov>
        <image>
          <width>400</width>
          <height>300</height>
          <format>R8G8B8</format>
        </image>
        <clip>
          <near>0.2</near>
          <far>300</far>
        </clip>
        <noise>
          <type>gaussian</type>
          <mean>0.0</mean>
          <stddev>0.007</stddev>
        </noise>
      </camera>

      <plugin name="camera_controller" filename="libgazebo_ros_camera.so">
        <alwaysOn>true</alwaysOn>
        <updateRate>0.0</updateRate>
        <cameraName>/follower/camera1</cameraName>
        <imageTopicName>image_raw</imageTopicName>
        <cameraInfoTopicName>camera_info</cameraInfoTopicName>
        <frameName>camera_link</frameName>
        <hackBaseline>0.07</hackBaseline>
        <distortionK1>0.0</distortionK1>
        <distortionK2>0.0</distortionK2>
        <distortionK3>0.0</distortionK3>
        <distortionT1>0.0</distortionT1>
        <distortionT2>0.0</distortionT2>
      </plugin>
    </sensor>
  </gazebo>

  <link name="camera_link">
    <inertial>
      <mass value="1"/>
      <origin rpy="0 0 0" xyz="0 0 0.1"/>
      <inertia ixx="0.00036458333333333335" ixy="0.0" ixz="0.0"
        iyy="0.00036458333333333335" iyz="0.0" izz="0.00031250000000000006"/>
    </inertial>
    <collision>
      <geometry>
        <cylinder length="0.05" radius="0.025" />
      </geometry>
    </collision>
    <visual>
      <origin rpy="0 0 0" xyz="0 0 0"/>
      <geometry>
        <cylinder length="0.05" radius="0.025" />
      </geometry>
    </visual>
  </link>

  <joint name="camera_joint" type="fixed">
    <origin rpy="0 0 0" xyz="0.23 0 0.07"/>
    <child link="camera_link"/>
    <parent link="link_chassis"/>
  </joint>

<gazebo>
<plugin name = "gazebo_ros_control" filename = "libgazebo_ros_control.so">
<robotNamespace>/robolab_ugv</robotNamespace>
</plugin>
</gazebo>

<transmission name = "front_right_wheel">
    <type>transmission_interface/SimpleTransmission</type>
    <actuator name = "front_right_motor">
        <mechanicalReduction>1</mechanicalReduction>
    </actuator>
    <joint name = "front_right_wheel_joint">
        <hardwareInterface>EffortJointInterface</hardwareInterface>
    </joint>
</transmission>

<transmission name = "front_left_wheel">
    <type>transmission_interface/SimpleTransmission</type>
    <actuator name = "front_left_motor">
        <mechanicalReduction>1</mechanicalReduction>
    </actuator>
    <joint name = "front_left_wheel_joint">
        <hardwareInterface>EffortJointInterface</hardwareInterface>
    </joint>
</transmission>

</robot>